<?xml version="1.0" encoding="utf-8"?>
<!-- This URDF was automatically created by SolidWorks to URDF Exporter and modified by SeaHI-Robot(https://github.com/SeaHI-Robot?tab=repositories)! Originally created by Stephen Brawner (brawner@gmail.com) 
     Commit Version: 1.6.0-4-g7f85cfe  Build Version: 1.6.7995.38578
     For more information, please see http://wiki.ros.org/sw_urdf_exporter -->
     
<robot name="duckbot" xmlns:xacro="http://wiki.ros.org/xacro">
  

<!-- LINK & JOINT DUMMY ########## FOOTPRINT ########## -->

  <link name="footprint"/>

  <joint name="footprint_joint" type="fixed">
    <parent link="footprint"/>
    <child link="base_link"/>    
  </joint>

  
<!-- LINK & JOINT ########## SUPPORT WHEELS ########## -->

  <link name="support_1">
    <visual name="">
      <origin xyz="0.085 0.0 -0.001" rpy="0.0 0.0 0.0"/>
      <geometry>
        <sphere radius="0.0025"/>
      </geometry>
      <material name="">
        <color rgba="1.0 0.0 0.0 1.0"/>
      </material>
    </visual>
    <collision>
      <origin xyz="0.085 0.0 -0.001" rpy="0.0 0.0 0.0"/>
      <geometry>
        <sphere radius="0.0025"/>
      </geometry>
    </collision>
  </link>

  <joint name="support_joint_1" type="fixed">
    <parent link="footprint"/>
    <child link="support_1"/>
  </joint>


  <link name="support_2">
    <visual name="">
      <origin xyz="-0.085 0.0 -0.001" rpy="0.0 0.0 0.0"/>
      <geometry>
        <sphere radius="0.0025"/>
      </geometry>
      <material name="">
        <color rgba="1.0 0.0 0.0 1.0"/>
      </material>
    </visual>
    <collision>
      <origin xyz="-0.085 0.0 -0.001" rpy="0.0 0.0 0.0"/>
      <geometry>
        <sphere radius="0.0025"/>
      </geometry>
    </collision>
  </link>

  <joint name="support_joint_2" type="fixed">
    <parent link="footprint"/>
    <child link="support_2"/>
  </joint>
  


<!-- LINK ########## BASE ########## -->
  <link name="base_link">
    <inertial>
      <origin
        xyz="0 0.005 3.8314E-18"
        rpy="0 0 0" />
      <mass
        value="0.1" />
      <inertia
        ixx="0.00038293"
        ixy="2.0091E-23"
        ixz="2.1411E-20"
        iyy="0.00088576"
        iyz="-2.0476E-37"
        izz="0.00050674" />
    </inertial>
    <visual>
      <origin
        xyz="0 0 0"
        rpy="0 0 0" />
      <geometry>
        <mesh
          filename="package://duckbot/meshes/base_link.STL" />
      </geometry>
      <material name="">
        <color rgba="0.79216 0.81961 0.93333 1" />
      </material>
    </visual>
    <collision>
      <origin
        xyz="0 0 0"
        rpy="0 0 0" />
      <geometry>
        <mesh
          filename="package://duckbot/meshes/base_link.STL" />
      </geometry>
    </collision>
  </link>

  


<!-- LINK ########## LEFT WHEEL ########## -->
  
  <link name="left_wheel_link">
    <inertial>
      <origin
        xyz="-0.002 0 0"
        rpy="0 0 1.5708" />
      <mass
        value="0.01" />
      <inertia
        ixx="6.2731E-08"
        ixy="9.8313E-21"
        ixz="1.6798E-21"
        iyy="3.2974E-08"
        iyz="8.2718E-25"
        izz="3.2974E-08" />
    </inertial>
    <visual>
      <origin
        xyz="0 0 0"
        rpy="0 0 1.5708" />
      <geometry>
        <mesh
          filename="package://duckbot/meshes/left_wheel_link.STL" />
      </geometry>
      <material
        name="">
        <color
          rgba="0.79216 0.81961 0.93333 1" />
      </material>
    </visual>
    <collision>
      <origin
        xyz="0 0 0"
        rpy="0 0 1.5708" />
      <geometry>
        <mesh
          filename="package://duckbot/meshes/left_wheel_link.STL" />
      </geometry>
    </collision>
  </link>




<!-- LINK ########## RIGHT WHEEL ########## -->
  
  <link name="right_wheel_link">
    <inertial>
      <origin
        xyz="-0.002 0 0"
        rpy="0 0 1.5708" />
      <mass
        value="0.01" />
      <inertia
        ixx="6.2731E-08"
        ixy="9.974E-21"
        ixz="-1.822E-24"
        iyy="3.2974E-08"
        iyz="-6.107E-37"
        izz="3.2974E-08" />
    </inertial>
    <visual>
      <origin
        xyz="0 0 0"
        rpy="0 0 1.5708" />
      <geometry>
        <mesh
          filename="package://duckbot/meshes/right_wheel_link.STL" />
      </geometry>
      <material
        name="">
        <color
          rgba="0.79216 0.81961 0.93333 1" />
      </material>
    </visual>
    <collision>
      <origin
        xyz="0 0 0"
        rpy="0 0 1.5708" />
      <geometry>
        <mesh
          filename="package://duckbot/meshes/right_wheel_link.STL" />
      </geometry>
    </collision>
  </link>



<!-- LINK & JOINT ########## VISUAL DUCK ########## -->

  <link name="duck">
    <visual name="duck_visual">
      <origin xyz="0.0 0.0 .001" rpy="1.5708 0.0 0.0"/>
      <geometry>
        <mesh filename="package://duckbot/meshes/duck.dae" />
      </geometry>
    </visual>
  </link>

  <joint name="duck_joint" type="fixed">
    <parent link="base_link"/>
    <child link="duck"/>
  </joint>



<!-- JOINT ########## RIGHT WHEEL ########## -->

  <joint name="right_joint" type="continuous">
    <origin
      xyz="0 -0.075833 0.005"
      rpy="0 0 0" />
    <parent
      link="base_link" />
    <child
      link="right_wheel_link" />
    <axis
      xyz="0 1 0" />
  </joint>



<!-- Joint ########## LEFT WHEEL ########## -->

  <joint name="left_joint" type="continuous">
    <origin
      xyz="0 0.075833 0.005"
      rpy="0 0 0" />
    <parent
      link="base_link" />
    <child
      link="left_wheel_link" />
    <axis
      xyz="0 1 0" />
  </joint>
</robot>
